Workbook

Sheet 설정
B2: 크레딧 배분 설정
B3: 노란색 셀만 수정하십시오. 값을 바꾸면 모든 시트가 자동 재계산됩니다.
B5: K-Credit — 지식 콘텐츠 기여
B6: 행위 | C6: 점수 | D6: 설계 의도
B7: 글 작성 | C7: 10 | D7: 기본 단위
B8: 첫 글 작성 (생애 1회) | C8: 50 | D8: 진입 장벽 제거 — 최대 병목에 최대 유인
B9: 댓글 작성 | C9: 3 | D9: 논의 참여 유도
B10: 좋아요 받음 | C10: 1 | D10: 반응 신호 (주 재원 아님)
B11: 좋아요 누름 | C11: 2 | D11: 읽기 중심 참여 유도 — 2차 팀회의 절충(누름만 상향)
B12: 위키 전환(published) | C12: 30 | D12: 검토 통과 = 품질 보증
B13: 타 문서가 인용·참조 | C13: 10 | D13: 재사용 실증
B16: S-Credit — 교육·전파 기여
B17: 행위 | C17: 점수 | D17: 설계 의도
B18: 교육·코칭 진행 (1회) | C18: 30 | D18: 직접 전파 · AX혁신팀 주요 활동
B19: 타 부서 도입 지원 | C19: 50 | D19: 확산 실증 — 가장 높은 가치
B22: 안전장치
B23: 항목 | C23: 값 | D23: 비고
B24: 월 상한 (1인) | C24: 500 | D24: 소수 독점 방지 — 부정 방지 아님
B25: 동일인 좋아요 1일 제한 | C25: 3 | D25: 동일 작성자에 대한 1일 최대 횟수
B28: 시뮬레이션 규모
B29: 항목 | C29: 값 | D29: 비고
B30: 전체 인원 | C30: 500 | D30: KIMM 전 직원 가정
B31: 작성자 수 | C31: 25 | D31: 초기 현실 가정 (전체의 5%)
B32: 열람 참여자 수 | C32: 120 | D32: 좋아요를 누르는 인원
B34: ※ 규모 값은 참고용 표기입니다. 실제 시뮬레이션 대상은 '활동로그' 시트의 데이터입니다.
B35: ※ 노란 셀(점수·안전장치)을 바꾸면 개인별정산·요약 시트가 즉시 재계산됩니다.
B36: ※ v1.1: '좋아요 누름' 1→2 상향(2차 팀회의 ③ 절충 — 받음 상향은 인기투표화 위험으로 보류).

Sheet 활동로그
B2: 활동 로그 (가상 데이터)
B3: 8월 런칭 후에는 이 시트를 실제 플랫폼 로그로 교체하면 그대로 정산 도구가 됩니다.
B5: ID | C5: 이름 | D5: 유형 | E5: 글 수 | F5: 첫 글 여부 | G5: 댓글 수 | H5: 받은 좋아요 | I5: 누른 좋아요 | J5: 위키 전환 | K5: 인용 받음 | L5: 교육 진행 | M5: 타부서 지원 | N5: 비고
B6: U001 | C6: 작성자 A | D6: 우수 생산자 | E6: 3 | F6: 1 | G6: 12 | H6: 45 | I6: 25 | J6: 2 | K6: 3 | L6: 0 | M6: 0 | N6: 양질의 글 · 독자 다수가 고르게 반응
B7: U002 | C7: 작성자 B | D7: 다작형 | E7: 15 | F7: 1 | G7: 5 | H7: 20 | I7: 10 | J7: 1 | K7: 0 | L7: 0 | M7: 0 | N7: 글 수는 많으나 건당 반응은 적음
B8: U003 | C8: 작성자 C | D8: 신규 진입자 | E8: 1 | F8: 1 | G8: 2 | H8: 18 | I8: 5 | J8: 1 | K8: 0 | L8: 0 | M8: 0 | N8: 첫 글 1건 · 반응 양호
B9: U004 | C9: 작성자 D | D9: 교육 중심 | E9: 2 | F9: 1 | G9: 8 | H9: 15 | I9: 30 | J9: 1 | K9: 1 | L9: 3 | M9: 1 | N9: 교육·코칭 중심 · S-Credit 비중 큼
B10: U005 | C10: 열람자 E | D10: 열람 전용 | E10: 0 | F10: 0 | G10: 6 | H10: 0 | I10: 21 | J10: 0 | K10: 0 | L10: 0 | M10: 0 | N10: 글 없음, 반응만 참여
B11: U006 | C11: 참여자 6 | D11: 일반 | E11: 1 | F11: 1 | G11: 1 | H11: 6 | I11: 20 | J11: 0 | K11: 0 | L11: 0 | M11: 0
B12: U007 | C12: 참여자 7 | D12: 일반 | E12: 1 | F12: 1 | G12: 4 | H12: 0 | I12: 16 | J12: 0 | K12: 0 | L12: 0 | M12: 0
B13: U008 | C13: 참여자 8 | D13: 일반 | E13: 2 | F13: 1 | G13: 3 | H13: 2 | I13: 7 | J13: 0 | K13: 1 | L13: 1 | M13: 0
B14: U009 | C14: 참여자 9 | D14: 일반 | E14: 0 | F14: 0 | G14: 6 | H14: 0 | I14: 18 | J14: 0 | K14: 0 | L14: 0 | M14: 0
B15: U010 | C15: 참여자 10 | D15: 일반 | E15: 1 | F15: 1 | G15: 5 | H15: 0 | I15: 18 | J15: 1 | K15: 0 | L15: 0 | M15: 0
B16: U011 | C16: 참여자 11 | D16: 일반 | E16: 0 | F16: 0 | G16: 4 | H16: 0 | I16: 4 | J16: 0 | K16: 0 | L16: 0 | M16: 0
B17: U012 | C17: 참여자 12 | D17: 일반 | E17: 2 | F17: 1 | G17: 1 | H17: 3 | I17: 18 | J17: 0 | K17: 1 | L17: 0 | M17: 0
B18: U013 | C18: 참여자 13 | D18: 일반 | E18: 0 | F18: 0 | G18: 4 | H18: 0 | I18: 18 | J18: 0 | K18: 0 | L18: 0 | M18: 0
B19: U014 | C19: 참여자 14 | D19: 일반 | E19: 1 | F19: 1 | G19: 0 | H19: 8 | I19: 2 | J19: 0 | K19: 1 | L19: 0 | M19: 0
B20: U015 | C20: 참여자 15 | D20: 일반 | E20: 2 | F20: 1 | G20: 5 | H20: 13 | I20: 10 | J20: 1 | K20: 1 | L20: 1 | M20: 0
B21: U016 | C21: 참여자 16 | D21: 일반 | E21: 1 | F21: 1 | G21: 2 | H21: 3 | I21: 5 | J21: 0 | K21: 0 | L21: 0 | M21: 0
B22: U017 | C22: 참여자 17 | D22: 일반 | E22: 2 | F22: 1 | G22: 3 | H22: 10 | I22: 14 | J22: 0 | K22: 1 | L22: 0 | M22: 0
... B30: U025 | C30: 참여자 25 | D30: 일반 | E30: 1 | F30: 1 | G30: 5 | H30: 3 | I30: 12 | J30: 1 | K30: 0 | L30: 0 | M30: 0
B32: ※ '첫 글 여부' 1 = 생애 첫 글 작성 (보너스 대상) · 0 = 해당 없음
B33: ※ 상위 5행은 회의 설명용 대표 유형이며, 나머지는 무작위 생성한 일반 참여자입니다.

Sheet 개인별정산
B2: 개인별 크레딧 정산
B3: 설정 시트의 점수를 바꾸면 이 시트가 자동으로 다시 계산됩니다.
B5: ID | C5: 이름 | D5: 유형 | E5: 글 | F5: 첫글보너스 | G5: 댓글 | H5: 좋아요받음 | I5: 좋아요누름 | J5: 위키전환 | K5: 인용 | L5: K-Credit 소계 | M5: S-Credit 소계 | N5: 합계(상한 전) | O5: 월 상한 적용 | P5: 최종 크레딧
B6: =활동로그!B6 -> U001 | C6: =활동로그!C6 -> 작성자 A | D6: =활동로그!D6 -> 우수 생산자 | E6: =활동로그!E6*설정!$C$7 -> 30 | F6: =활동로그!F6*설정!$C$8 -> 50 | G6: =활동로그!G6*설정!$C$9 -> 36 | H6: =활동로그!H6*설정!$C$10 -> 45 | I6: =활동로그!I6*설정!$C$11 -> 50 | J6: =활동로그!J6*설정!$C$12 -> 60 | K6: =활동로그!K6*설정!$C$13 -> 30 | L6: =SUM(E6:K6) -> 301 | M6: =활동로그!L6*설정!$C$18+활동로그!M6*설정!$C$19 -> 0 | N6: =L6+M6 -> 301 | O6: =IF(N6>설정!$C$24,"초과","-") -> - | P6: =MIN(N6,설정!$C$24) -> 301
B7: =활동로그!B7 -> U002 | C7: =활동로그!C7 -> 작성자 B | D7: =활동로그!D7 -> 다작형 | E7: =활동로그!E7*설정!$C$7 -> 150 | F7: =활동로그!F7*설정!$C$8 -> 50 | G7: =활동로그!G7*설정!$C$9 -> 15 | H7: =활동로그!H7*설정!$C$10 -> 20 | I7: =활동로그!I7*설정!$C$11 -> 20 | J7: =활동로그!J7*설정!$C$12 -> 30 | K7: =활동로그!K7*설정!$C$13 -> 0 | L7: =SUM(E7:K7) -> 285 | M7: =활동로그!L7*설정!$C$18+활동로그!M7*설정!$C$19 -> 0 | N7: =L7+M7 -> 285 | O7: =IF(N7>설정!$C$24,"초과","-") -> - | P7: =MIN(N7,설정!$C$24) -> 285
B8: =활동로그!B8 -> U003 | C8: =활동로그!C8 -> 작성자 C | D8: =활동로그!D8 -> 신규 진입자 | E8: =활동로그!E8*설정!$C$7 -> 10 | F8: =활동로그!F8*설정!$C$8 -> 50 | G8: =활동로그!G8*설정!$C$9 -> 6 | H8: =활동로그!H8*설정!$C$10 -> 18 | I8: =활동로그!I8*설정!$C$11 -> 10 | J8: =활동로그!J8*설정!$C$12 -> 30 | K8: =활동로그!K8*설정!$C$13 -> 0 | L8: =SUM(E8:K8) -> 124 | M8: =활동로그!L8*설정!$C$18+활동로그!M8*설정!$C$19 -> 0 | N8: =L8+M8 -> 124 | O8: =IF(N8>설정!$C$24,"초과","-") -> - | P8: =MIN(N8,설정!$C$24) -> 124
B9: =활동로그!B9 -> U004 | C9: =활동로그!C9 -> 작성자 D | D9: =활동로그!D9 -> 교육 중심 | E9: =활동로그!E9*설정!$C$7 -> 20 | F9: =활동로그!F9*설정!$C$8 -> 50 | G9: =활동로그!G9*설정!$C$9 -> 24 | H9: =활동로그!H9*설정!$C$10 -> 15 | I9: =활동로그!I9*설정!$C$11 -> 60 | J9: =활동로그!J9*설정!$C$12 -> 30 | K9: =활동로그!K9*설정!$C$13 -> 10 | L9: =SUM(E9:K9) -> 209 | M9: =활동로그!L9*설정!$C$18+활동로그!M9*설정!$C$19 -> 140 | N9: =L9+M9 -> 349 | O9: =IF(N9>설정!$C$24,"초과","-") -> - | P9: =MIN(N9,설정!$C$24) -> 349
B10: =활동로그!B10 -> U005 | C10: =활동로그!C10 -> 열람자 E | D10: =활동로그!D10 -> 열람 전용 | E10: =활동로그!E10*설정!$C$7 -> 0 | F10: =활동로그!F10*설정!$C$8 -> 0 | G10: =활동로그!G10*설정!$C$9 -> 18 | H10: =활동로그!H10*설정!$C$10 -> 0 | I10: =활동로그!I10*설정!$C$11 -> 42 | J10: =활동로그!J10*설정!$C$12 -> 0 | K10: =활동로그!K10*설정!$C$13 -> 0 | L10: =SUM(E10:K10) -> 60 | M10: =활동로그!L10*설정!$C$18+활동로그!M10*설정!$C$19 -> 0 | N10: =L10+M10 -> 60 | O10: =IF(N10>설정!$C$24,"초과","-") -> - | P10: =MIN(N10,설정!$C$24) -> 60
B11: =활동로그!B11 -> U006 | C11: =활동로그!C11 -> 참여자 6 | D11: =활동로그!D11 -> 일반 | E11: =활동로그!E11*설정!$C$7 -> 10 | F11: =활동로그!F11*설정!$C$8 -> 50 | G11: =활동로그!G11*설정!$C$9 -> 3 | H11: =활동로그!H11*설정!$C$10 -> 6 | I11: =활동로그!I11*설정!$C$11 -> 40 | J11: =활동로그!J11*설정!$C$12 -> 0 | K11: =활동로그!K11*설정!$C$13 -> 0 | L11: =SUM(E11:K11) -> 109 | M11: =활동로그!L11*설정!$C$18+활동로그!M11*설정!$C$19 -> 0 | N11: =L11+M11 -> 109 | O11: =IF(N11>설정!$C$24,"초과","-") -> - | P11: =MIN(N11,설정!$C$24) -> 109
B12: =활동로그!B12 -> U007 | C12: =활동로그!C12 -> 참여자 7 | D12: =활동로그!D12 -> 일반 | E12: =활동로그!E12*설정!$C$7 -> 10 | F12: =활동로그!F12*설정!$C$8 -> 50 | G12: =활동로그!G12*설정!$C$9 -> 12 | H12: =활동로그!H12*설정!$C$10 -> 0 | I12: =활동로그!I12*설정!$C$11 -> 32 | J12: =활동로그!J12*설정!$C$12 -> 0 | K12: =활동로그!K12*설정!$C$13 -> 0 | L12: =SUM(E12:K12) -> 104 | M12: =활동로그!L12*설정!$C$18+활동로그!M12*설정!$C$19 -> 0 | N12: =L12+M12 -> 104 | O12: =IF(N12>설정!$C$24,"초과","-") -> - | P12: =MIN(N12,설정!$C$24) -> 104
B13: =활동로그!B13 -> U008 | C13: =활동로그!C13 -> 참여자 8 | D13: =활동로그!D13 -> 일반 | E13: =활동로그!E13*설정!$C$7 -> 20 | F13: =활동로그!F13*설정!$C$8 -> 50 | G13: =활동로그!G13*설정!$C$9 -> 9 | H13: =활동로그!H13*설정!$C$10 -> 2 | I13: =활동로그!I13*설정!$C$11 -> 14 | J13: =활동로그!J13*설정!$C$12 -> 0 | K13: =활동로그!K13*설정!$C$13 -> 10 | L13: =SUM(E13:K13) -> 105 | M13: =활동로그!L13*설정!$C$18+활동로그!M13*설정!$C$19 -> 30 | N13: =L13+M13 -> 135 | O13: =IF(N13>설정!$C$24,"초과","-") -> - | P13: =MIN(N13,설정!$C$24) -> 135
B14: =활동로그!B14 -> U009 | C14: =활동로그!C14 -> 참여자 9 | D14: =활동로그!D14 -> 일반 | E14: =활동로그!E14*설정!$C$7 -> 0 | F14: =활동로그!F14*설정!$C$8 -> 0 | G14: =활동로그!G14*설정!$C$9 -> 18 | H14: =활동로그!H14*설정!$C$10 -> 0 | I14: =활동로그!I14*설정!$C$11 -> 36 | J14: =활동로그!J14*설정!$C$12 -> 0 | K14: =활동로그!K14*설정!$C$13 -> 0 | L14: =SUM(E14:K14) -> 54 | M14: =활동로그!L14*설정!$C$18+활동로그!M14*설정!$C$19 -> 0 | N14: =L14+M14 -> 54 | O14: =IF(N14>설정!$C$24,"초과","-") -> - | P14: =MIN(N14,설정!$C$24) -> 54
B15: =활동로그!B15 -> U010 | C15: =활동로그!C15 -> 참여자 10 | D15: =활동로그!D15 -> 일반 | E15: =활동로그!E15*설정!$C$7 -> 10 | F15: =활동로그!F15*설정!$C$8 -> 50 | G15: =활동로그!G15*설정!$C$9 -> 15 | H15: =활동로그!H15*설정!$C$10 -> 0 | I15: =활동로그!I15*설정!$C$11 -> 36 | J15: =활동로그!J15*설정!$C$12 -> 30 | K15: =활동로그!K15*설정!$C$13 -> 0 | L15: =SUM(E15:K15) -> 141 | M15: =활동로그!L15*설정!$C$18+활동로그!M15*설정!$C$19 -> 0 | N15: =L15+M15 -> 141 | O15: =IF(N15>설정!$C$24,"초과","-") -> - | P15: =MIN(N15,설정!$C$24) -> 141
B16: =활동로그!B16 -> U011 | C16: =활동로그!C16 -> 참여자 11 | D16: =활동로그!D16 -> 일반 | E16: =활동로그!E16*설정!$C$7 -> 0 | F16: =활동로그!F16*설정!$C$8 -> 0 | G16: =활동로그!G16*설정!$C$9 -> 12 | H16: =활동로그!H16*설정!$C$10 -> 0 | I16: =활동로그!I16*설정!$C$11 -> 8 | J16: =활동로그!J16*설정!$C$12 -> 0 | K16: =활동로그!K16*설정!$C$13 -> 0 | L16: =SUM(E16:K16) -> 20 | M16: =활동로그!L16*설정!$C$18+활동로그!M16*설정!$C$19 -> 0 | N16: =L16+M16 -> 20 | O16: =IF(N16>설정!$C$24,"초과","-") -> - | P16: =MIN(N16,설정!$C$24) -> 20
B17: =활동로그!B17 -> U012 | C17: =활동로그!C17 -> 참여자 12 | D17: =활동로그!D17 -> 일반 | E17: =활동로그!E17*설정!$C$7 -> 20 | F17: =활동로그!F17*설정!$C$8 -> 50 | G17: =활동로그!G17*설정!$C$9 -> 3 | H17: =활동로그!H17*설정!$C$10 -> 3 | I17: =활동로그!I17*설정!$C$11 -> 36 | J17: =활동로그!J17*설정!$C$12 -> 0 | K17: =활동로그!K17*설정!$C$13 -> 10 | L17: =SUM(E17:K17) -> 122 | M17: =활동로그!L17*설정!$C$18+활동로그!M17*설정!$C$19 -> 0 | N17: =L17+M17 -> 122 | O17: =IF(N17>설정!$C$24,"초과","-") -> - | P17: =MIN(N17,설정!$C$24) -> 122
... B30: =활동로그!B30 -> U025 | C30: =활동로그!C30 -> 참여자 25 | D30: =활동로그!D30 -> 일반 | E30: =활동로그!E30*설정!$C$7 -> 10 | F30: =활동로그!F30*설정!$C$8 -> 50 | G30: =활동로그!G30*설정!$C$9 -> 15 | H30: =활동로그!H30*설정!$C$10 -> 3 | I30: =활동로그!I30*설정!$C$11 -> 24 | J30: =활동로그!J30*설정!$C$12 -> 30 | K30: =활동로그!K30*설정!$C$13 -> 0 | L30: =SUM(E30:K30) -> 132 | M30: =활동로그!L30*설정!$C$18+활동로그!M30*설정!$C$19 -> 0 | N30: =L30+M30 -> 132 | O30: =IF(N30>설정!$C$24,"초과","-") -> - | P30: =MIN(N30,설정!$C$24) -> 132
D31: 합계 | L31: =SUM(L6:L30) -> 2958 | M31: =SUM(M6:M30) -> 320 | N31: =SUM(N6:N30) -> 3278 | P31: =SUM(P6:P30) -> 3278

Sheet 사전등록 시나리오
B2: 사전 등록분 크레딧 처리 시나리오
B3: 운영(안) §5.2 결정용 — AX혁신팀이 런칭 전 사전 등록한 콘텐츠에 크레딧을 부여할지 비교
B5: 가정
B6: 항목 | C6: 값 | D6: 비고
B7: AX혁신팀 인원 | C7: 16 | D7: 기획보고서 v3 명단
B8: 1인당 사전 등록 건수 | C8: 3 | D8: 런칭 시점 30~50건 확보 목표 기준
B9: 사전 등록분 첫글 해당 | C9: 1 | D9: 1 = 사전 등록이 생애 첫 글이 됨 / 0 = 아님
B10: 사전 등록분 예상 좋아요 | C10: 5 | D10: 런칭 직후 열람 집중으로 건당 반응
B13: 혁신팀 1인당 사전 등록 점수
B14: 구성 요소 | C14: 점수 | D14: 산식
B15: 글 작성 | C15: =$C$8*설정!$C$7 -> 30 | D15: 등록 건수 × 글 작성 점수
B16: 첫 글 보너스 | C16: =$C$9*설정!$C$8 -> 50 | D16: 첫글 해당 여부 × 보너스
B17: 좋아요 받음 | C17: =$C$8*$C$10*설정!$C$10 -> 15 | D17: 등록 건수 × 건당 좋아요 × 점수
B18: 1인당 합계 | C18: =SUM(C15:C17) -> 95 | D18: 사전 등록만으로 획득하는 점수
B21: 부여 / 미부여 비교
B22: 지표 | C22: ① 부여 | D22: ② 미부여 | E22: 해석
B23: 혁신팀 1인 점수 (사전분) | C23: =C18 -> 95 | D23: 0 | E23: 미부여 시 사전 등록은 점수에 반영되지 않음
B24: 혁신팀 16인 합계 | C24: =C18*C7 -> 1520 | D24: 0 | E24: 제도 전체에 유입되는 점수 총량
B25: 일반 참여자 평균 (참고) | C25: =IFERROR(개인별정산!P31/COUNTA(개인별정산!B6:B30),0) -> 131.12 | D25: =IFERROR(개인별정산!P31/COUNTA(개인별정산!B6:B30),0) -> 131.12 | E25: '개인별정산' 시트 기준 1인 평균
B26: 혁신팀 1인 / 일반 평균 배수 | C26: =IFERROR(C23/C25,0) -> 0.72452715 | D26: =0 -> 0 | E26: 1.0배를 넘으면 사전 등록만으로 평균을 상회
B27: 월 상한(500) 대비 소진율 | C27: =IFERROR(C18/설정!$C$24,0) -> 0.19 | D27: =0 -> 0 | E27: 사전 등록만으로 상한의 몇 %를 채우는가
B30: 판단 참고
B31: ① 부여 시 — 혁신팀 16명이 런칭 첫 달 상위권을 차지할 가능성이 높다.
B32: 사전 등록은 '플랫폼 준비 작업'이지 자발적 참여가 아니므로, 일반 참여자에게는
B33: 따라잡을 수 없는 격차로 보일 수 있다.
B34: ② 미부여 시 — 사전 등록 협조에 대한 유인이 없다. 다만 이번 건은 기존 모임의
B35: 축적 자료를 옮기는 작업이어서 추가 부담이 크지 않아, 유인 부재의 영향은 제한적이다.
B36: ③ 절충(운영안 제안) — 크레딧 산정에서는 제외하되 「플랫폼 구축 기여」로 별도 기록하여
B37: 연말 단장 추천 시 근거 자료로 활용한다.
B39: ※ 노란 셀(가정)을 바꾸면 비교 수치가 즉시 재계산됩니다.
B40: ※ '일반 참여자 평균'은 활동로그의 가상 데이터 기준이므로 참고값입니다.

Sheet 요약
B2: 시뮬레이션 요약
B3: 설정 시트의 점수 배분을 조정하면서 아래 지표 변화를 확인하십시오.
B5: 지표 | C5: 값 | D5: 판단 기준
B6: 참여자 수 (로그 등재) | C6: =COUNTA(개인별정산!B6:B30) -> 25 | D6: —
B7: 글을 쓴 사람 수 | C7: =COUNTIF(활동로그!E6:E30,">0") -> 20 | D7: 초기 20~30명이면 정상
B8: 첫 글 보너스 수령자 | C8: =COUNTIF(활동로그!F6:F30,1) -> 20 | D8: 많을수록 신규 진입이 활발
B9: 전체 크레딧 총량 | C9: =개인별정산!P31 -> 3278 | D9: —
B10: 1인 평균 | C10: =IFERROR(개인별정산!P31/COUNTA(개인별정산!B6:B30),0) -> 131.12 | D10: —
B11: 최고 점수 | C11: =MAX(개인별정산!P6:P30) -> 349 | D11: —
B12: 월 상한 도달자 | C12: =COUNTIF(개인별정산!O6:O30,"초과") -> 0 | D12: 0~2명이 적정 · 3명 이상이면 상한 상향 검토
B13: 상위 3인 점유율 | C13: =IFERROR(SUM(LARGE(개인별정산!P6:P30,1),LARGE(개인별정산!P6:P30,2),LARGE(개인별정산!P6:P30,3))/개인별정산!P31,0) -> 0.2852349 | D13: 40% 초과 시 독점 우려
B14: 첫글보너스 비중 | C14: =IFERROR(SUM(개인별정산!F6:F30)/개인별정산!N31,0) -> 0.30506406 | D14: 30% 초과 시 보너스 과다 검토
B17: 대표 유형 비교 (회의 설명용)
B18: 유형 | C18: 활동 요약 | D18: 최종 크레딧 | E18: 해석
B19: 작성자 A · 우수 생산자 | C19: 글 3 · 좋아요 45 · 위키 2 | D19: =개인별정산!P6 -> 301 | E19: 고품질 다수 반응 — 최상위
B20: 작성자 B · 다작형 | C20: 글 15 · 좋아요 20 · 위키 1 | D20: =개인별정산!P7 -> 285 | E20: 물량 대비 효율 낮음
B21: 작성자 C · 신규 진입자 | C21: 글 1 · 좋아요 18 · 첫글 | D21: =개인별정산!P8 -> 124 | E21: 첫글 보너스로 진입 유인 확보
B22: 작성자 D · 교육 중심 | C22: 교육 3회 · 타부서 지원 1 | D22: =개인별정산!P9 -> 349 | E22: S-Credit 비중이 큰 유형
B23: 열람자 E · 열람 전용 | C23: 글 0 · 좋아요 21회 누름 | D23: =개인별정산!P10 -> 60 | E23: 소액이나 참여 자체를 인정
B26: 회의에서 확인할 논점
B27: ① 첫 글 보너스 점수 — 설정 시트 C8 을 50 → 20 으로 낮추면 신규 진입자(작성자 C) 점수와
B28: '첫글보너스 비중' 지표가 어떻게 변하는지 확인. 현재 비중이 30%를 넘으면 보너스 과다.
B29: ② 다작 대비 품질 — 현재 배분에서는 글 3건(작성자 A)과 글 15건(작성자 B)의 점수 차이가 크지 않다.
B30: 글 작성 점수를 낮추고 위키 전환 점수를 올리면 품질 쪽으로 기운다.
B31: ③ 월 상한 수준 — 상한 도달자가 0명이면 상한이 사실상 작동하지 않는 것이다.
B32: 실제 로그가 쌓인 뒤 상위권 분포를 보고 재조정한다.
B33: ④ 열람 전용 참여(열람자 E) — 글 없이 좋아요만 눌러도 점수가 쌓인다. 이 수준이 적정한지 판단 필요.
B35: 단장 부여 점수 배분 (평가점수배분 시트)
B36: 점수 수령 인원 | C36: =평가점수배분!E43 -> 25 | D36: —
B37: 소진 점수 / 총 재원 | C37: =평가점수배분!E44&" / "&평가점수배분!D7 -> 53 / 100 | D37: 재원 내이면 전원 배분

Sheet 평가점수배분
B2: 연구단장 부여 점수 — 규칙 기반 배분 시뮬레이션
B3: 연구단장 의견(2026. 8.) 반영 — 노란 셀만 수정하십시오. 개인별정산의 최종 크레딧을 기준으로 자동 계산됩니다.
B5: 배분 설정
B6: 항목 | D6: 값 | E6: 비고
B7: 총 재원 (점) | D7: 100 | E7: 단장 부여 점수 총량 — "100점 내외"
B8: 인당 최대 (점) | D8: 5 | E8: 0.5점 단위
B9: 배분 단위 (점) | D9: 0.5 | E9: 올림·배분 모두 이 단위
B10: 정규화 기준 순위 | D10: 1 | E10: 1 = 최고점 기준 · 3 = 3위 점수 기준(상위 극단값 완화)
B12: 정규화 기준 크레딧 | D12: =LARGE(개인별정산!$P$6:$P$30,$D$10) -> 349 | E12: 이 크레딧이 5.0점(인당 최대)으로 환산되는 기준
B14: 배분 결과 (크레딧 내림차순)
B15: 순위 | C15: ID | D15: 이름 | E15: 최종 크레딧 | F15: 정규화 점수 | G15: 누적 소요 | H15: 배분 점수 | I15: 조정값(내부용)
B16: 1 | C16: =INDEX(개인별정산!$B$6:$B$30,MATCH(LARGE($I$16:$I$40,B16),$I$16:$I$40,0)) -> U004 | D16: =INDEX(개인별정산!$C$6:$C$30,MATCH(LARGE($I$16:$I$40,B16),$I$16:$I$40,0)) -> 작성자 D | E16: =ROUND(LARGE($I$16:$I$40,B16),0) -> 349 | F16: =IF(E16<=0,0,MIN($D$8,CEILING(E16/$D$12*$D$8,$D$9))) -> 5 | G16: =0+H16 -> 5 | H16: =IF(0>=$D$7,0,MIN(F16,FLOOR($D$7-0,$D$9))) -> 5 | I16: =개인별정산!P6+(30-6)*0.000001 -> 301.00002
B17: 2 | C17: =INDEX(개인별정산!$B$6:$B$30,MATCH(LARGE($I$16:$I$40,B17),$I$16:$I$40,0)) -> U001 | D17: =INDEX(개인별정산!$C$6:$C$30,MATCH(LARGE($I$16:$I$40,B17),$I$16:$I$40,0)) -> 작성자 A | E17: =ROUND(LARGE($I$16:$I$40,B17),0) -> 301 | F17: =IF(E17<=0,0,MIN($D$8,CEILING(E17/$D$12*$D$8,$D$9))) -> 4.5 | G17: =G16+H17 -> 9.5 | H17: =IF(G16>=$D$7,0,MIN(F17,FLOOR($D$7-G16,$D$9))) -> 4.5 | I17: =개인별정산!P7+(30-7)*0.000001 -> 285.00002
B18: 3 | C18: =INDEX(개인별정산!$B$6:$B$30,MATCH(LARGE($I$16:$I$40,B18),$I$16:$I$40,0)) -> U002 | D18: =INDEX(개인별정산!$C$6:$C$30,MATCH(LARGE($I$16:$I$40,B18),$I$16:$I$40,0)) -> 작성자 B | E18: =ROUND(LARGE($I$16:$I$40,B18),0) -> 285 | F18: =IF(E18<=0,0,MIN($D$8,CEILING(E18/$D$12*$D$8,$D$9))) -> 4.5 | G18: =G17+H18 -> 14 | H18: =IF(G17>=$D$7,0,MIN(F18,FLOOR($D$7-G17,$D$9))) -> 4.5 | I18: =개인별정산!P8+(30-8)*0.000001 -> 124.00002
B19: 4 | C19: =INDEX(개인별정산!$B$6:$B$30,MATCH(LARGE($I$16:$I$40,B19),$I$16:$I$40,0)) -> U015 | D19: =INDEX(개인별정산!$C$6:$C$30,MATCH(LARGE($I$16:$I$40,B19),$I$16:$I$40,0)) -> 참여자 15 | E19: =ROUND(LARGE($I$16:$I$40,B19),0) -> 188 | F19: =IF(E19<=0,0,MIN($D$8,CEILING(E19/$D$12*$D$8,$D$9))) -> 3 | G19: =G18+H19 -> 17 | H19: =IF(G18>=$D$7,0,MIN(F19,FLOOR($D$7-G18,$D$9))) -> 3 | I19: =개인별정산!P9+(30-9)*0.000001 -> 349.00002
B20: 5 | C20: =INDEX(개인별정산!$B$6:$B$30,MATCH(LARGE($I$16:$I$40,B20),$I$16:$I$40,0)) -> U023 | D20: =INDEX(개인별정산!$C$6:$C$30,MATCH(LARGE($I$16:$I$40,B20),$I$16:$I$40,0)) -> 참여자 23 | E20: =ROUND(LARGE($I$16:$I$40,B20),0) -> 153 | F20: =IF(E20<=0,0,MIN($D$8,CEILING(E20/$D$12*$D$8,$D$9))) -> 2.5 | G20: =G19+H20 -> 19.5 | H20: =IF(G19>=$D$7,0,MIN(F20,FLOOR($D$7-G19,$D$9))) -> 2.5 | I20: =개인별정산!P10+(30-10)*0.000001 -> 60.00002
B21: 6 | C21: =INDEX(개인별정산!$B$6:$B$30,MATCH(LARGE($I$16:$I$40,B21),$I$16:$I$40,0)) -> U020 | D21: =INDEX(개인별정산!$C$6:$C$30,MATCH(LARGE($I$16:$I$40,B21),$I$16:$I$40,0)) -> 참여자 20 | E21: =ROUND(LARGE($I$16:$I$40,B21),0) -> 152 | F21: =IF(E21<=0,0,MIN($D$8,CEILING(E21/$D$12*$D$8,$D$9))) -> 2.5 | G21: =G20+H21 -> 22 | H21: =IF(G20>=$D$7,0,MIN(F21,FLOOR($D$7-G20,$D$9))) -> 2.5 | I21: =개인별정산!P11+(30-11)*0.000001 -> 109.00002
B22: 7 | C22: =INDEX(개인별정산!$B$6:$B$30,MATCH(LARGE($I$16:$I$40,B22),$I$16:$I$40,0)) -> U010 | D22: =INDEX(개인별정산!$C$6:$C$30,MATCH(LARGE($I$16:$I$40,B22),$I$16:$I$40,0)) -> 참여자 10 | E22: =ROUND(LARGE($I$16:$I$40,B22),0) -> 141 | F22: =IF(E22<=0,0,MIN($D$8,CEILING(E22/$D$12*$D$8,$D$9))) -> 2.5 | G22: =G21+H22 -> 24.5 | H22: =IF(G21>=$D$7,0,MIN(F22,FLOOR($D$7-G21,$D$9))) -> 2.5 | I22: =개인별정산!P12+(30-12)*0.000001 -> 104.00002
B23: 8 | C23: =INDEX(개인별정산!$B$6:$B$30,MATCH(LARGE($I$16:$I$40,B23),$I$16:$I$40,0)) -> U022 | D23: =INDEX(개인별정산!$C$6:$C$30,MATCH(LARGE($I$16:$I$40,B23),$I$16:$I$40,0)) -> 참여자 22 | E23: =ROUND(LARGE($I$16:$I$40,B23),0) -> 139 | F23: =IF(E23<=0,0,MIN($D$8,CEILING(E23/$D$12*$D$8,$D$9))) -> 2 | G23: =G22+H23 -> 26.5 | H23: =IF(G22>=$D$7,0,MIN(F23,FLOOR($D$7-G22,$D$9))) -> 2 | I23: =개인별정산!P13+(30-13)*0.000001 -> 135.00002
B24: 9 | C24: =INDEX(개인별정산!$B$6:$B$30,MATCH(LARGE($I$16:$I$40,B24),$I$16:$I$40,0)) -> U021 | D24: =INDEX(개인별정산!$C$6:$C$30,MATCH(LARGE($I$16:$I$40,B24),$I$16:$I$40,0)) -> 참여자 21 | E24: =ROUND(LARGE($I$16:$I$40,B24),0) -> 136 | F24: =IF(E24<=0,0,MIN($D$8,CEILING(E24/$D$12*$D$8,$D$9))) -> 2 | G24: =G23+H24 -> 28.5 | H24: =IF(G23>=$D$7,0,MIN(F24,FLOOR($D$7-G23,$D$9))) -> 2 | I24: =개인별정산!P14+(30-14)*0.000001 -> 54.000016
B25: 10 | C25: =INDEX(개인별정산!$B$6:$B$30,MATCH(LARGE($I$16:$I$40,B25),$I$16:$I$40,0)) -> U008 | D25: =INDEX(개인별정산!$C$6:$C$30,MATCH(LARGE($I$16:$I$40,B25),$I$16:$I$40,0)) -> 참여자 8 | E25: =ROUND(LARGE($I$16:$I$40,B25),0) -> 135 | F25: =IF(E25<=0,0,MIN($D$8,CEILING(E25/$D$12*$D$8,$D$9))) -> 2 | G25: =G24+H25 -> 30.5 | H25: =IF(G24>=$D$7,0,MIN(F25,FLOOR($D$7-G24,$D$9))) -> 2 | I25: =개인별정산!P15+(30-15)*0.000001 -> 141.00001
B26: 11 | C26: =INDEX(개인별정산!$B$6:$B$30,MATCH(LARGE($I$16:$I$40,B26),$I$16:$I$40,0)) -> U025 | D26: =INDEX(개인별정산!$C$6:$C$30,MATCH(LARGE($I$16:$I$40,B26),$I$16:$I$40,0)) -> 참여자 25 | E26: =ROUND(LARGE($I$16:$I$40,B26),0) -> 132 | F26: =IF(E26<=0,0,MIN($D$8,CEILING(E26/$D$12*$D$8,$D$9))) -> 2 | G26: =G25+H26 -> 32.5 | H26: =IF(G25>=$D$7,0,MIN(F26,FLOOR($D$7-G25,$D$9))) -> 2 | I26: =개인별정산!P16+(30-16)*0.000001 -> 20.000014
B27: 12 | C27: =INDEX(개인별정산!$B$6:$B$30,MATCH(LARGE($I$16:$I$40,B27),$I$16:$I$40,0)) -> U017 | D27: =INDEX(개인별정산!$C$6:$C$30,MATCH(LARGE($I$16:$I$40,B27),$I$16:$I$40,0)) -> 참여자 17 | E27: =ROUND(LARGE($I$16:$I$40,B27),0) -> 127 | F27: =IF(E27<=0,0,MIN($D$8,CEILING(E27/$D$12*$D$8,$D$9))) -> 2 | G27: =G26+H27 -> 34.5 | H27: =IF(G26>=$D$7,0,MIN(F27,FLOOR($D$7-G26,$D$9))) -> 2 | I27: =개인별정산!P17+(30-17)*0.000001 -> 122.00001
B28: 13 | C28: =INDEX(개인별정산!$B$6:$B$30,MATCH(LARGE($I$16:$I$40,B28),$I$16:$I$40,0)) -> U003 | D28: =INDEX(개인별정산!$C$6:$C$30,MATCH(LARGE($I$16:$I$40,B28),$I$16:$I$40,0)) -> 작성자 C | E28: =ROUND(LARGE($I$16:$I$40,B28),0) -> 124 | F28: =IF(E28<=0,0,MIN($D$8,CEILING(E28/$D$12*$D$8,$D$9))) -> 2 | G28: =G27+H28 -> 36.5 | H28: =IF(G27>=$D$7,0,MIN(F28,FLOOR($D$7-G27,$D$9))) -> 2 | I28: =개인별정산!P18+(30-18)*0.000001 -> 48.000012
B29: 14 | C29: =INDEX(개인별정산!$B$6:$B$30,MATCH(LARGE($I$16:$I$40,B29),$I$16:$I$40,0)) -> U012 | D29: =INDEX(개인별정산!$C$6:$C$30,MATCH(LARGE($I$16:$I$40,B29),$I$16:$I$40,0)) -> 참여자 12 | E29: =ROUND(LARGE($I$16:$I$40,B29),0) -> 122 | F29: =IF(E29<=0,0,MIN($D$8,CEILING(E29/$D$12*$D$8,$D$9))) -> 2 | G29: =G28+H29 -> 38.5 | H29: =IF(G28>=$D$7,0,MIN(F29,FLOOR($D$7-G28,$D$9))) -> 2 | I29: =개인별정산!P19+(30-19)*0.000001 -> 82.000011
B30: 15 | C30: =INDEX(개인별정산!$B$6:$B$30,MATCH(LARGE($I$16:$I$40,B30),$I$16:$I$40,0)) -> U006 | D30: =INDEX(개인별정산!$C$6:$C$30,MATCH(LARGE($I$16:$I$40,B30),$I$16:$I$40,0)) -> 참여자 6 | E30: =ROUND(LARGE($I$16:$I$40,B30),0) -> 109 | F30: =IF(E30<=0,0,MIN($D$8,CEILING(E30/$D$12*$D$8,$D$9))) -> 2 | G30: =G29+H30 -> 40.5 | H30: =IF(G29>=$D$7,0,MIN(F30,FLOOR($D$7-G29,$D$9))) -> 2 | I30: =개인별정산!P20+(30-20)*0.000001 -> 188.00001
B31: 16 | C31: =INDEX(개인별정산!$B$6:$B$30,MATCH(LARGE($I$16:$I$40,B31),$I$16:$I$40,0)) -> U019 | D31: =INDEX(개인별정산!$C$6:$C$30,MATCH(LARGE($I$16:$I$40,B31),$I$16:$I$40,0)) -> 참여자 19 | E31: =ROUND(LARGE($I$16:$I$40,B31),0) -> 106 | F31: =IF(E31<=0,0,MIN($D$8,CEILING(E31/$D$12*$D$8,$D$9))) -> 2 | G31: =G30+H31 -> 42.5 | H31: =IF(G30>=$D$7,0,MIN(F31,FLOOR($D$7-G30,$D$9))) -> 2 | I31: =개인별정산!P21+(30-21)*0.000001 -> 79.000009
B32: 17 | C32: =INDEX(개인별정산!$B$6:$B$30,MATCH(LARGE($I$16:$I$40,B32),$I$16:$I$40,0)) -> U007 | D32: =INDEX(개인별정산!$C$6:$C$30,MATCH(LARGE($I$16:$I$40,B32),$I$16:$I$40,0)) -> 참여자 7 | E32: =ROUND(LARGE($I$16:$I$40,B32),0) -> 104 | F32: =IF(E32<=0,0,MIN($D$8,CEILING(E32/$D$12*$D$8,$D$9))) -> 1.5 | G32: =G31+H32 -> 44 | H32: =IF(G31>=$D$7,0,MIN(F32,FLOOR($D$7-G31,$D$9))) -> 1.5 | I32: =개인별정산!P22+(30-22)*0.000001 -> 127.00001
B33: 18 | C33: =INDEX(개인별정산!$B$6:$B$30,MATCH(LARGE($I$16:$I$40,B33),$I$16:$I$40,0)) -> U024 | D33: =INDEX(개인별정산!$C$6:$C$30,MATCH(LARGE($I$16:$I$40,B33),$I$16:$I$40,0)) -> 참여자 24 | E33: =ROUND(LARGE($I$16:$I$40,B33),0) -> 94 | F33: =IF(E33<=0,0,MIN($D$8,CEILING(E33/$D$12*$D$8,$D$9))) -> 1.5 | G33: =G32+H33 -> 45.5 | H33: =IF(G32>=$D$7,0,MIN(F33,FLOOR($D$7-G32,$D$9))) -> 1.5 | I33: =개인별정산!P23+(30-23)*0.000001 -> 38.000007
B34: 19 | C34: =INDEX(개인별정산!$B$6:$B$30,MATCH(LARGE($I$16:$I$40,B34),$I$16:$I$40,0)) -> U014 | D34: =INDEX(개인별정산!$C$6:$C$30,MATCH(LARGE($I$16:$I$40,B34),$I$16:$I$40,0)) -> 참여자 14 | E34: =ROUND(LARGE($I$16:$I$40,B34),0) -> 82 | F34: =IF(E34<=0,0,MIN($D$8,CEILING(E34/$D$12*$D$8,$D$9))) -> 1.5 | G34: =G33+H34 -> 47 | H34: =IF(G33>=$D$7,0,MIN(F34,FLOOR($D$7-G33,$D$9))) -> 1.5 | I34: =개인별정산!P24+(30-24)*0.000001 -> 106.00001
B35: 20 | C35: =INDEX(개인별정산!$B$6:$B$30,MATCH(LARGE($I$16:$I$40,B35),$I$16:$I$40,0)) -> U016 | D35: =INDEX(개인별정산!$C$6:$C$30,MATCH(LARGE($I$16:$I$40,B35),$I$16:$I$40,0)) -> 참여자 16 | E35: =ROUND(LARGE($I$16:$I$40,B35),0) -> 79 | F35: =IF(E35<=0,0,MIN($D$8,CEILING(E35/$D$12*$D$8,$D$9))) -> 1.5 | G35: =G34+H35 -> 48.5 | H35: =IF(G34>=$D$7,0,MIN(F35,FLOOR($D$7-G34,$D$9))) -> 1.5 | I35: =개인별정산!P25+(30-25)*0.000001 -> 152
B36: 21 | C36: =INDEX(개인별정산!$B$6:$B$30,MATCH(LARGE($I$16:$I$40,B36),$I$16:$I$40,0)) -> U005 | D36: =INDEX(개인별정산!$C$6:$C$30,MATCH(LARGE($I$16:$I$40,B36),$I$16:$I$40,0)) -> 열람자 E | E36: =ROUND(LARGE($I$16:$I$40,B36),0) -> 60 | F36: =IF(E36<=0,0,MIN($D$8,CEILING(E36/$D$12*$D$8,$D$9))) -> 1 | G36: =G35+H36 -> 49.5 | H36: =IF(G35>=$D$7,0,MIN(F36,FLOOR($D$7-G35,$D$9))) -> 1 | I36: =개인별정산!P26+(30-26)*0.000001 -> 136
B37: 22 | C37: =INDEX(개인별정산!$B$6:$B$30,MATCH(LARGE($I$16:$I$40,B37),$I$16:$I$40,0)) -> U009 | D37: =INDEX(개인별정산!$C$6:$C$30,MATCH(LARGE($I$16:$I$40,B37),$I$16:$I$40,0)) -> 참여자 9 | E37: =ROUND(LARGE($I$16:$I$40,B37),0) -> 54 | F37: =IF(E37<=0,0,MIN($D$8,CEILING(E37/$D$12*$D$8,$D$9))) -> 1 | G37: =G36+H37 -> 50.5 | H37: =IF(G36>=$D$7,0,MIN(F37,FLOOR($D$7-G36,$D$9))) -> 1 | I37: =개인별정산!P27+(30-27)*0.000001 -> 139
B38: 23 | C38: =INDEX(개인별정산!$B$6:$B$30,MATCH(LARGE($I$16:$I$40,B38),$I$16:$I$40,0)) -> U013 | D38: =INDEX(개인별정산!$C$6:$C$30,MATCH(LARGE($I$16:$I$40,B38),$I$16:$I$40,0)) -> 참여자 13 | E38: =ROUND(LARGE($I$16:$I$40,B38),0) -> 48 | F38: =IF(E38<=0,0,MIN($D$8,CEILING(E38/$D$12*$D$8,$D$9))) -> 1 | G38: =G37+H38 -> 51.5 | H38: =IF(G37>=$D$7,0,MIN(F38,FLOOR($D$7-G37,$D$9))) -> 1 | I38: =개인별정산!P28+(30-28)*0.000001 -> 153
B39: 24 | C39: =INDEX(개인별정산!$B$6:$B$30,MATCH(LARGE($I$16:$I$40,B39),$I$16:$I$40,0)) -> U018 | D39: =INDEX(개인별정산!$C$6:$C$30,MATCH(LARGE($I$16:$I$40,B39),$I$16:$I$40,0)) -> 참여자 18 | E39: =ROUND(LARGE($I$16:$I$40,B39),0) -> 38 | F39: =IF(E39<=0,0,MIN($D$8,CEILING(E39/$D$12*$D$8,$D$9))) -> 1 | G39: =G38+H39 -> 52.5 | H39: =IF(G38>=$D$7,0,MIN(F39,FLOOR($D$7-G38,$D$9))) -> 1 | I39: =개인별정산!P29+(30-29)*0.000001 -> 94.000001
B40: 25 | C40: =INDEX(개인별정산!$B$6:$B$30,MATCH(LARGE($I$16:$I$40,B40),$I$16:$I$40,0)) -> U011 | D40: =INDEX(개인별정산!$C$6:$C$30,MATCH(LARGE($I$16:$I$40,B40),$I$16:$I$40,0)) -> 참여자 11 | E40: =ROUND(LARGE($I$16:$I$40,B40),0) -> 20 | F40: =IF(E40<=0,0,MIN($D$8,CEILING(E40/$D$12*$D$8,$D$9))) -> 0.5 | G40: =G39+H40 -> 53 | H40: =IF(G39>=$D$7,0,MIN(F40,FLOOR($D$7-G39,$D$9))) -> 0.5 | I40: =개인별정산!P30+(30-30)*0.000001 -> 132
B42: 배분 요약
B43: 점수를 받는 인원 | E43: =COUNTIF(H16:H40,">0") -> 25 | F43: 명
B44: 소진 점수 합계 | E44: =SUM(H16:H40) -> 53 | F44: =IF(SUM(H16:H40)>=$D$7,"재원 전액 소진 — 하위 순위 컷 발생","재원 내 — 전원 배분") -> 재원 내 — 전원 배분
B45: 잔여 재원 | E45: =$D$7-SUM(H16:H40) -> 47 | F45: 점
...
